use crate::instance::Bound;
use crate::panic::PanicException;
use crate::type_object::PyTypeInfo;
use crate::types::any::PyAnyMethods;
use crate::types::{
    string::PyStringMethods, traceback::PyTracebackMethods, typeobject::PyTypeMethods, PyTraceback,
    PyType,
};
use crate::{
    exceptions::{self, PyBaseException},
    ffi,
};
use crate::{Borrowed, BoundObject, Py, PyAny, PyObject, Python};
#[allow(deprecated)]
use crate::{IntoPy, ToPyObject};
use std::borrow::Cow;
use std::ffi::CStr;

mod err_state;
mod impls;

use crate::conversion::IntoPyObject;
use err_state::{PyErrState, PyErrStateLazyFnOutput, PyErrStateNormalized};
use std::convert::Infallible;

/// Represents a Python exception.
///
/// To avoid needing access to [`Python`] in `Into` conversions to create `PyErr` (thus improving
/// compatibility with `?` and other Rust errors) this type supports creating exceptions instances
/// in a lazy fashion, where the full Python object for the exception is created only when needed.
///
/// Accessing the contained exception in any way, such as with [`value`](PyErr::value),
/// [`get_type`](PyErr::get_type), or [`is_instance`](PyErr::is_instance)
/// will create the full exception object if it was not already created.
pub struct PyErr {
    state: PyErrState,
}

// The inner value is only accessed through ways that require proving the gil is held
#[cfg(feature = "nightly")]
unsafe impl crate::marker::Ungil for PyErr {}

/// Represents the result of a Python call.
pub type PyResult<T> = Result<T, PyErr>;

/// Error that indicates a failure to convert a PyAny to a more specific Python type.
#[derive(Debug)]
pub struct DowncastError<'a, 'py> {
    from: Borrowed<'a, 'py, PyAny>,
    to: Cow<'static, str>,
}

impl<'a, 'py> DowncastError<'a, 'py> {
    /// Create a new `PyDowncastError` representing a failure to convert the object
    /// `from` into the type named in `to`.
    pub fn new(from: &'a Bound<'py, PyAny>, to: impl Into<Cow<'static, str>>) -> Self {
        DowncastError {
            from: from.as_borrowed(),
            to: to.into(),
        }
    }
    pub(crate) fn new_from_borrowed(
        from: Borrowed<'a, 'py, PyAny>,
        to: impl Into<Cow<'static, str>>,
    ) -> Self {
        DowncastError {
            from,
            to: to.into(),
        }
    }
}

/// Error that indicates a failure to convert a PyAny to a more specific Python type.
#[derive(Debug)]
pub struct DowncastIntoError<'py> {
    from: Bound<'py, PyAny>,
    to: Cow<'static, str>,
}

impl<'py> DowncastIntoError<'py> {
    /// Create a new `DowncastIntoError` representing a failure to convert the object
    /// `from` into the type named in `to`.
    pub fn new(from: Bound<'py, PyAny>, to: impl Into<Cow<'static, str>>) -> Self {
        DowncastIntoError {
            from,
            to: to.into(),
        }
    }

    /// Consumes this `DowncastIntoError` and returns the original object, allowing continued
    /// use of it after a failed conversion.
    ///
    /// See [`downcast_into`][PyAnyMethods::downcast_into] for an example.
    pub fn into_inner(self) -> Bound<'py, PyAny> {
        self.from
    }
}

/// Helper conversion trait that allows to use custom arguments for lazy exception construction.
pub trait PyErrArguments: Send + Sync {
    /// Arguments for exception
    fn arguments(self, py: Python<'_>) -> PyObject;
}

impl<T> PyErrArguments for T
where
    T: for<'py> IntoPyObject<'py> + Send + Sync,
{
    fn arguments(self, py: Python<'_>) -> PyObject {
        // FIXME: `arguments` should become fallible
        match self.into_pyobject(py) {
            Ok(obj) => obj.into_any().unbind(),
            Err(e) => panic!("Converting PyErr arguments failed: {}", e.into()),
        }
    }
}

impl PyErr {
    /// Creates a new PyErr of type `T`.
    ///
    /// `args` can be:
    /// * a tuple: the exception instance will be created using the equivalent to the Python
    ///   expression `T(*tuple)`
    /// * any other value: the exception instance will be created using the equivalent to the Python
    ///   expression `T(value)`
    ///
    /// This exception instance will be initialized lazily. This avoids the need for the Python GIL
    /// to be held, but requires `args` to be `Send` and `Sync`. If `args` is not `Send` or `Sync`,
    /// consider using [`PyErr::from_value`] instead.
    ///
    /// If `T` does not inherit from `BaseException`, then a `TypeError` will be returned.
    ///
    /// If calling T's constructor with `args` raises an exception, that exception will be returned.
    ///
    /// # Examples
    ///
    /// ```
    /// use pyo3::prelude::*;
    /// use pyo3::exceptions::PyTypeError;
    ///
    /// #[pyfunction]
    /// fn always_throws() -> PyResult<()> {
    ///     Err(PyErr::new::<PyTypeError, _>("Error message"))
    /// }
    /// #
    /// # Python::with_gil(|py| {
    /// #     let fun = pyo3::wrap_pyfunction!(always_throws, py).unwrap();
    /// #     let err = fun.call0().expect_err("called a function that should always return an error but the return value was Ok");
    /// #     assert!(err.is_instance_of::<PyTypeError>(py))
    /// # });
    /// ```
    ///
    /// In most cases, you can use a concrete exception's constructor instead:
    ///
    /// ```
    /// use pyo3::prelude::*;
    /// use pyo3::exceptions::PyTypeError;
    ///
    /// #[pyfunction]
    /// fn always_throws() -> PyResult<()> {
    ///     Err(PyTypeError::new_err("Error message"))
    /// }
    /// #
    /// # Python::with_gil(|py| {
    /// #     let fun = pyo3::wrap_pyfunction!(always_throws, py).unwrap();
    /// #     let err = fun.call0().expect_err("called a function that should always return an error but the return value was Ok");
    /// #     assert!(err.is_instance_of::<PyTypeError>(py))
    /// # });
    /// ```
    #[inline]
    pub fn new<T, A>(args: A) -> PyErr
    where
        T: PyTypeInfo,
        A: PyErrArguments + Send + Sync + 'static,
    {
        PyErr::from_state(PyErrState::lazy(Box::new(move |py| {
            PyErrStateLazyFnOutput {
                ptype: T::type_object(py).into(),
                pvalue: args.arguments(py),
            }
        })))
    }

    /// Constructs a new PyErr from the given Python type and arguments.
    ///
    /// `ty` is the exception type; usually one of the standard exceptions
    /// like `exceptions::PyRuntimeError`.
    ///
    /// `args` is either a tuple or a single value, with the same meaning as in [`PyErr::new`].
    ///
    /// If `ty` does not inherit from `BaseException`, then a `TypeError` will be returned.
    ///
    /// If calling `ty` with `args` raises an exception, that exception will be returned.
    pub fn from_type<A>(ty: Bound<'_, PyType>, args: A) -> PyErr
    where
        A: PyErrArguments + Send + Sync + 'static,
    {
        PyErr::from_state(PyErrState::lazy_arguments(ty.unbind().into_any(), args))
    }

    /// Creates a new PyErr.
    ///
    /// If `obj` is a Python exception object, the PyErr will contain that object.
    ///
    /// If `obj` is a Python exception type object, this is equivalent to `PyErr::from_type(obj, ())`.
    ///
    /// Otherwise, a `TypeError` is created.
    ///
    /// # Examples
    /// ```rust
    /// use pyo3::prelude::*;
    /// use pyo3::PyTypeInfo;
    /// use pyo3::exceptions::PyTypeError;
    /// use pyo3::types::PyString;
    ///
    /// Python::with_gil(|py| {
    ///     // Case #1: Exception object
    ///     let err = PyErr::from_value(PyTypeError::new_err("some type error")
    ///         .value(py).clone().into_any());
    ///     assert_eq!(err.to_string(), "TypeError: some type error");
    ///
    ///     // Case #2: Exception type
    ///     let err = PyErr::from_value(PyTypeError::type_object(py).into_any());
    ///     assert_eq!(err.to_string(), "TypeError: ");
    ///
    ///     // Case #3: Invalid exception value
    ///     let err = PyErr::from_value(PyString::new(py, "foo").into_any());
    ///     assert_eq!(
    ///         err.to_string(),
    ///         "TypeError: exceptions must derive from BaseException"
    ///     );
    /// });
    /// ```
    pub fn from_value(obj: Bound<'_, PyAny>) -> PyErr {
        let state = match obj.downcast_into::<PyBaseException>() {
            Ok(obj) => PyErrState::normalized(PyErrStateNormalized::new(obj)),
            Err(err) => {
                // Assume obj is Type[Exception]; let later normalization handle if this
                // is not the case
                let obj = err.into_inner();
                let py = obj.py();
                PyErrState::lazy_arguments(obj.unbind(), py.None())
            }
        };

        PyErr::from_state(state)
    }

    /// Returns the type of this exception.
    ///
    /// # Examples
    /// ```rust
    /// use pyo3::{prelude::*, exceptions::PyTypeError, types::PyType};
    ///
    /// Python::with_gil(|py| {
    ///     let err: PyErr = PyTypeError::new_err(("some type error",));
    ///     assert!(err.get_type(py).is(&PyType::new::<PyTypeError>(py)));
    /// });
    /// ```
    pub fn get_type<'py>(&self, py: Python<'py>) -> Bound<'py, PyType> {
        self.normalized(py).ptype(py)
    }

    /// Returns the value of this exception.
    ///
    /// # Examples
    ///
    /// ```rust
    /// use pyo3::{exceptions::PyTypeError, PyErr, Python};
    ///
    /// Python::with_gil(|py| {
    ///     let err: PyErr = PyTypeError::new_err(("some type error",));
    ///     assert!(err.is_instance_of::<PyTypeError>(py));
    ///     assert_eq!(err.value(py).to_string(), "some type error");
    /// });
    /// ```
    pub fn value<'py>(&self, py: Python<'py>) -> &Bound<'py, PyBaseException> {
        self.normalized(py).pvalue.bind(py)
    }

    /// Consumes self to take ownership of the exception value contained in this error.
    pub fn into_value(self, py: Python<'_>) -> Py<PyBaseException> {
        // NB technically this causes one reference count increase and decrease in quick succession
        // on pvalue, but it's probably not worth optimizing this right now for the additional code
        // complexity.
        let normalized = self.normalized(py);
        let exc = normalized.pvalue.clone_ref(py);
        if let Some(tb) = normalized.ptraceback(py) {
            unsafe {
                ffi::PyException_SetTraceback(exc.as_ptr(), tb.as_ptr());
            }
        }
        exc
    }

    /// Returns the traceback of this exception object.
    ///
    /// # Examples
    /// ```rust
    /// use pyo3::{exceptions::PyTypeError, Python};
    ///
    /// Python::with_gil(|py| {
    ///     let err = PyTypeError::new_err(("some type error",));
    ///     assert!(err.traceback(py).is_none());
    /// });
    /// ```
    pub fn traceback<'py>(&self, py: Python<'py>) -> Option<Bound<'py, PyTraceback>> {
        self.normalized(py).ptraceback(py)
    }

    /// Gets whether an error is present in the Python interpreter's global state.
    #[inline]
    pub fn occurred(_: Python<'_>) -> bool {
        unsafe { !ffi::PyErr_Occurred().is_null() }
    }

    /// Takes the current error from the Python interpreter's global state and clears the global
    /// state. If no error is set, returns `None`.
    ///
    /// If the error is a `PanicException` (which would have originated from a panic in a pyo3
    /// callback) then this function will resume the panic.
    ///
    /// Use this function when it is not known if an error should be present. If the error is
    /// expected to have been set, for example from [`PyErr::occurred`] or by an error return value
    /// from a C FFI function, use [`PyErr::fetch`].
    pub fn take(py: Python<'_>) -> Option<PyErr> {
        let state = PyErrStateNormalized::take(py)?;
        let pvalue = state.pvalue.bind(py);
        if pvalue.get_type().as_ptr() == PanicException::type_object_raw(py).cast() {
            let msg: String = pvalue
                .str()
                .map(|py_str| py_str.to_string_lossy().into())
                .unwrap_or_else(|_| String::from("Unwrapped panic from Python code"));
            Self::print_panic_and_unwind(py, PyErrState::normalized(state), msg)
        }

        Some(PyErr::from_state(PyErrState::normalized(state)))
    }

    fn print_panic_and_unwind(py: Python<'_>, state: PyErrState, msg: String) -> ! {
        eprintln!("--- PyO3 is resuming a panic after fetching a PanicException from Python. ---");
        eprintln!("Python stack trace below:");

        state.restore(py);

        unsafe {
            ffi::PyErr_PrintEx(0);
        }

        std::panic::resume_unwind(Box::new(msg))
    }

    /// Equivalent to [PyErr::take], but when no error is set:
    ///  - Panics in debug mode.
    ///  - Returns a `SystemError` in release mode.
    ///
    /// This behavior is consistent with Python's internal handling of what happens when a C return
    /// value indicates an error occurred but the global error state is empty. (A lack of exception
    /// should be treated as a bug in the code which returned an error code but did not set an
    /// exception.)
    ///
    /// Use this function when the error is expected to have been set, for example from
    /// [PyErr::occurred] or by an error return value from a C FFI function.
    #[cfg_attr(debug_assertions, track_caller)]
    #[inline]
    pub fn fetch(py: Python<'_>) -> PyErr {
        const FAILED_TO_FETCH: &str = "attempted to fetch exception but none was set";
        match PyErr::take(py) {
            Some(err) => err,
            #[cfg(debug_assertions)]
            None => panic!("{}", FAILED_TO_FETCH),
            #[cfg(not(debug_assertions))]
            None => exceptions::PySystemError::new_err(FAILED_TO_FETCH),
        }
    }

    /// Creates a new exception type with the given name and docstring.
    ///
    /// - `base` can be an existing exception type to subclass, or a tuple of classes.
    /// - `dict` specifies an optional dictionary of class variables and methods.
    /// - `doc` will be the docstring seen by python users.
    ///
    ///
    /// # Errors
    ///
    /// This function returns an error if `name` is not of the form `<module>.<ExceptionName>`.
    pub fn new_type<'py>(
        py: Python<'py>,
        name: &CStr,
        doc: Option<&CStr>,
        base: Option<&Bound<'py, PyType>>,
        dict: Option<PyObject>,
    ) -> PyResult<Py<PyType>> {
        let base: *mut ffi::PyObject = match base {
            None => std::ptr::null_mut(),
            Some(obj) => obj.as_ptr(),
        };

        let dict: *mut ffi::PyObject = match dict {
            None => std::ptr::null_mut(),
            Some(obj) => obj.as_ptr(),
        };

        let doc_ptr = match doc.as_ref() {
            Some(c) => c.as_ptr(),
            None => std::ptr::null(),
        };

        let ptr = unsafe { ffi::PyErr_NewExceptionWithDoc(name.as_ptr(), doc_ptr, base, dict) };

        unsafe { Py::from_owned_ptr_or_err(py, ptr) }
    }

    /// Prints a standard traceback to `sys.stderr`.
    pub fn display(&self, py: Python<'_>) {
        #[cfg(Py_3_12)]
        unsafe {
            ffi::PyErr_DisplayException(self.value(py).as_ptr())
        }

        #[cfg(not(Py_3_12))]
        unsafe {
            // keep the bound `traceback` alive for entire duration of
            // PyErr_Display. if we inline this, the `Bound` will be dropped
            // after the argument got evaluated, leading to call with a dangling
            // pointer.
            let traceback = self.traceback(py);
            let type_bound = self.get_type(py);
            ffi::PyErr_Display(
                type_bound.as_ptr(),
                self.value(py).as_ptr(),
                traceback
                    .as_ref()
                    .map_or(std::ptr::null_mut(), |traceback| traceback.as_ptr()),
            )
        }
    }

    /// Calls `sys.excepthook` and then prints a standard traceback to `sys.stderr`.
    pub fn print(&self, py: Python<'_>) {
        self.clone_ref(py).restore(py);
        unsafe { ffi::PyErr_PrintEx(0) }
    }

    /// Calls `sys.excepthook` and then prints a standard traceback to `sys.stderr`.
    ///
    /// Additionally sets `sys.last_{type,value,traceback,exc}` attributes to this exception.
    pub fn print_and_set_sys_last_vars(&self, py: Python<'_>) {
        self.clone_ref(py).restore(py);
        unsafe { ffi::PyErr_PrintEx(1) }
    }

    /// Returns true if the current exception matches the exception in `exc`.
    ///
    /// If `exc` is a class object, this also returns `true` when `self` is an instance of a subclass.
    /// If `exc` is a tuple, all exceptions in the tuple (and recursively in subtuples) are searched for a match.
    pub fn matches<'py, T>(&self, py: Python<'py>, exc: T) -> Result<bool, T::Error>
    where
        T: IntoPyObject<'py>,
    {
        Ok(self.is_instance(py, &exc.into_pyobject(py)?.into_any().as_borrowed()))
    }

    /// Returns true if the current exception is instance of `T`.
    #[inline]
    pub fn is_instance(&self, py: Python<'_>, ty: &Bound<'_, PyAny>) -> bool {
        let type_bound = self.get_type(py);
        (unsafe { ffi::PyErr_GivenExceptionMatches(type_bound.as_ptr(), ty.as_ptr()) }) != 0
    }

    /// Returns true if the current exception is instance of `T`.
    #[inline]
    pub fn is_instance_of<T>(&self, py: Python<'_>) -> bool
    where
        T: PyTypeInfo,
    {
        self.is_instance(py, &T::type_object(py))
    }

    /// Writes the error back to the Python interpreter's global state.
    /// This is the opposite of `PyErr::fetch()`.
    #[inline]
    pub fn restore(self, py: Python<'_>) {
        self.state.restore(py)
    }

    /// Reports the error as unraisable.
    ///
    /// This calls `sys.unraisablehook()` using the current exception and obj argument.
    ///
    /// This method is useful to report errors in situations where there is no good mechanism
    /// to report back to the Python land.  In Python this is used to indicate errors in
    /// background threads or destructors which are protected.  In Rust code this is commonly
    /// useful when you are calling into a Python callback which might fail, but there is no
    /// obvious way to handle this error other than logging it.
    ///
    /// Calling this method has the benefit that the error goes back into a standardized callback
    /// in Python which for instance allows unittests to ensure that no unraisable error
    /// actually happend by hooking `sys.unraisablehook`.
    ///
    /// Example:
    /// ```rust
    /// # use pyo3::prelude::*;
    /// # use pyo3::exceptions::PyRuntimeError;
    /// # fn failing_function() -> PyResult<()> { Err(PyRuntimeError::new_err("foo")) }
    /// # fn main() -> PyResult<()> {
    /// Python::with_gil(|py| {
    ///     match failing_function() {
    ///         Err(pyerr) => pyerr.write_unraisable(py, None),
    ///         Ok(..) => { /* do something here */ }
    ///     }
    ///     Ok(())
    /// })
    /// # }
    #[inline]
    pub fn write_unraisable(self, py: Python<'_>, obj: Option<&Bound<'_, PyAny>>) {
        self.restore(py);
        unsafe { ffi::PyErr_WriteUnraisable(obj.map_or(std::ptr::null_mut(), Bound::as_ptr)) }
    }

    /// Issues a warning message.
    ///
    /// May return an `Err(PyErr)` if warnings-as-errors is enabled.
    ///
    /// Equivalent to `warnings.warn()` in Python.
    ///
    /// The `category` should be one of the `Warning` classes available in
    /// [`pyo3::exceptions`](crate::exceptions), or a subclass.  The Python
    /// object can be retrieved using [`Python::get_type()`].
    ///
    /// Example:
    /// ```rust
    /// # use pyo3::prelude::*;
    /// # use pyo3::ffi::c_str;
    /// # fn main() -> PyResult<()> {
    /// Python::with_gil(|py| {
    ///     let user_warning = py.get_type::<pyo3::exceptions::PyUserWarning>();
    ///     PyErr::warn(py, &user_warning, c_str!("I am warning you"), 0)?;
    ///     Ok(())
    /// })
    /// # }
    /// ```
    pub fn warn<'py>(
        py: Python<'py>,
        category: &Bound<'py, PyAny>,
        message: &CStr,
        stacklevel: i32,
    ) -> PyResult<()> {
        error_on_minusone(py, unsafe {
            ffi::PyErr_WarnEx(
                category.as_ptr(),
                message.as_ptr(),
                stacklevel as ffi::Py_ssize_t,
            )
        })
    }

    /// Issues a warning message, with more control over the warning attributes.
    ///
    /// May return a `PyErr` if warnings-as-errors is enabled.
    ///
    /// Equivalent to `warnings.warn_explicit()` in Python.
    ///
    /// The `category` should be one of the `Warning` classes available in
    /// [`pyo3::exceptions`](crate::exceptions), or a subclass.
    pub fn warn_explicit<'py>(
        py: Python<'py>,
        category: &Bound<'py, PyAny>,
        message: &CStr,
        filename: &CStr,
        lineno: i32,
        module: Option<&CStr>,
        registry: Option<&Bound<'py, PyAny>>,
    ) -> PyResult<()> {
        let module_ptr = match module {
            None => std::ptr::null_mut(),
            Some(s) => s.as_ptr(),
        };
        let registry: *mut ffi::PyObject = match registry {
            None => std::ptr::null_mut(),
            Some(obj) => obj.as_ptr(),
        };
        error_on_minusone(py, unsafe {
            ffi::PyErr_WarnExplicit(
                category.as_ptr(),
                message.as_ptr(),
                filename.as_ptr(),
                lineno,
                module_ptr,
                registry,
            )
        })
    }

    /// Clone the PyErr. This requires the GIL, which is why PyErr does not implement Clone.
    ///
    /// # Examples
    /// ```rust
    /// use pyo3::{exceptions::PyTypeError, PyErr, Python, prelude::PyAnyMethods};
    /// Python::with_gil(|py| {
    ///     let err: PyErr = PyTypeError::new_err(("some type error",));
    ///     let err_clone = err.clone_ref(py);
    ///     assert!(err.get_type(py).is(&err_clone.get_type(py)));
    ///     assert!(err.value(py).is(err_clone.value(py)));
    ///     match err.traceback(py) {
    ///         None => assert!(err_clone.traceback(py).is_none()),
    ///         Some(tb) => assert!(err_clone.traceback(py).unwrap().is(&tb)),
    ///     }
    /// });
    /// ```
    #[inline]
    pub fn clone_ref(&self, py: Python<'_>) -> PyErr {
        PyErr::from_state(PyErrState::normalized(self.normalized(py).clone_ref(py)))
    }

    /// Return the cause (either an exception instance, or None, set by `raise ... from ...`)
    /// associated with the exception, as accessible from Python through `__cause__`.
    pub fn cause(&self, py: Python<'_>) -> Option<PyErr> {
        use crate::ffi_ptr_ext::FfiPtrExt;
        let obj =
            unsafe { ffi::PyException_GetCause(self.value(py).as_ptr()).assume_owned_or_opt(py) };
        // PyException_GetCause is documented as potentially returning PyNone, but only GraalPy seems to actually do that
        #[cfg(GraalPy)]
        if let Some(cause) = &obj {
            if cause.is_none() {
                return None;
            }
        }
        obj.map(Self::from_value)
    }

    /// Set the cause associated with the exception, pass `None` to clear it.
    pub fn set_cause(&self, py: Python<'_>, cause: Option<Self>) {
        let value = self.value(py);
        let cause = cause.map(|err| err.into_value(py));
        unsafe {
            // PyException_SetCause _steals_ a reference to cause, so must use .into_ptr()
            ffi::PyException_SetCause(
                value.as_ptr(),
                cause.map_or(std::ptr::null_mut(), Py::into_ptr),
            );
        }
    }

    #[inline]
    fn from_state(state: PyErrState) -> PyErr {
        PyErr { state }
    }

    #[inline]
    fn normalized(&self, py: Python<'_>) -> &PyErrStateNormalized {
        self.state.as_normalized(py)
    }
}

impl std::fmt::Debug for PyErr {
    fn fmt(&self, f: &mut std::fmt::Formatter<'_>) -> Result<(), std::fmt::Error> {
        Python::with_gil(|py| {
            f.debug_struct("PyErr")
                .field("type", &self.get_type(py))
                .field("value", self.value(py))
                .field(
                    "traceback",
                    &self.traceback(py).map(|tb| match tb.format() {
                        Ok(s) => s,
                        Err(err) => {
                            err.write_unraisable(py, Some(&tb));
                            // It would be nice to format what we can of the
                            // error, but we can't guarantee that the error
                            // won't have another unformattable traceback inside
                            // it and we want to avoid an infinite recursion.
                            format!("<unformattable {:?}>", tb)
                        }
                    }),
                )
                .finish()
        })
    }
}

impl std::fmt::Display for PyErr {
    fn fmt(&self, f: &mut std::fmt::Formatter<'_>) -> std::fmt::Result {
        Python::with_gil(|py| {
            let value = self.value(py);
            let type_name = value.get_type().qualname().map_err(|_| std::fmt::Error)?;
            write!(f, "{}", type_name)?;
            if let Ok(s) = value.str() {
                write!(f, ": {}", &s.to_string_lossy())
            } else {
                write!(f, ": <exception str() failed>")
            }
        })
    }
}

impl std::error::Error for PyErr {}

#[allow(deprecated)]
impl IntoPy<PyObject> for PyErr {
    #[inline]
    fn into_py(self, py: Python<'_>) -> PyObject {
        self.into_pyobject(py).unwrap().into_any().unbind()
    }
}

#[allow(deprecated)]
impl ToPyObject for PyErr {
    #[inline]
    fn to_object(&self, py: Python<'_>) -> PyObject {
        self.into_pyobject(py).unwrap().into_any().unbind()
    }
}

#[allow(deprecated)]
impl IntoPy<PyObject> for &PyErr {
    #[inline]
    fn into_py(self, py: Python<'_>) -> PyObject {
        self.into_pyobject(py).unwrap().into_any().unbind()
    }
}

impl<'py> IntoPyObject<'py> for PyErr {
    type Target = PyBaseException;
    type Output = Bound<'py, Self::Target>;
    type Error = Infallible;

    #[inline]
    fn into_pyobject(self, py: Python<'py>) -> Result<Self::Output, Self::Error> {
        Ok(self.into_value(py).into_bound(py))
    }
}

impl<'py> IntoPyObject<'py> for &PyErr {
    type Target = PyBaseException;
    type Output = Bound<'py, Self::Target>;
    type Error = Infallible;

    #[inline]
    fn into_pyobject(self, py: Python<'py>) -> Result<Self::Output, Self::Error> {
        self.clone_ref(py).into_pyobject(py)
    }
}

struct PyDowncastErrorArguments {
    from: Py<PyType>,
    to: Cow<'static, str>,
}

impl PyErrArguments for PyDowncastErrorArguments {
    fn arguments(self, py: Python<'_>) -> PyObject {
        const FAILED_TO_EXTRACT: Cow<'_, str> = Cow::Borrowed("<failed to extract type name>");
        let from = self.from.bind(py).qualname();
        let from = match &from {
            Ok(qn) => qn.to_cow().unwrap_or(FAILED_TO_EXTRACT),
            Err(_) => FAILED_TO_EXTRACT,
        };
        format!("'{}' object cannot be converted to '{}'", from, self.to)
            .into_pyobject(py)
            .unwrap()
            .into_any()
            .unbind()
    }
}

/// Python exceptions that can be converted to [`PyErr`].
///
/// This is used to implement [`From<Bound<'_, T>> for PyErr`].
///
/// Users should not need to implement this trait directly. It is implemented automatically in the
/// [`crate::import_exception!`] and [`crate::create_exception!`] macros.
pub trait ToPyErr {}

impl<'py, T> std::convert::From<Bound<'py, T>> for PyErr
where
    T: ToPyErr,
{
    #[inline]
    fn from(err: Bound<'py, T>) -> PyErr {
        PyErr::from_value(err.into_any())
    }
}

/// Convert `DowncastError` to Python `TypeError`.
impl std::convert::From<DowncastError<'_, '_>> for PyErr {
    fn from(err: DowncastError<'_, '_>) -> PyErr {
        let args = PyDowncastErrorArguments {
            from: err.from.get_type().into(),
            to: err.to,
        };

        exceptions::PyTypeError::new_err(args)
    }
}

impl std::error::Error for DowncastError<'_, '_> {}

impl std::fmt::Display for DowncastError<'_, '_> {
    fn fmt(&self, f: &mut std::fmt::Formatter<'_>) -> Result<(), std::fmt::Error> {
        display_downcast_error(f, &self.from, &self.to)
    }
}

/// Convert `DowncastIntoError` to Python `TypeError`.
impl std::convert::From<DowncastIntoError<'_>> for PyErr {
    fn from(err: DowncastIntoError<'_>) -> PyErr {
        let args = PyDowncastErrorArguments {
            from: err.from.get_type().into(),
            to: err.to,
        };

        exceptions::PyTypeError::new_err(args)
    }
}

impl std::error::Error for DowncastIntoError<'_> {}

impl std::fmt::Display for DowncastIntoError<'_> {
    fn fmt(&self, f: &mut std::fmt::Formatter<'_>) -> Result<(), std::fmt::Error> {
        display_downcast_error(f, &self.from, &self.to)
    }
}

fn display_downcast_error(
    f: &mut std::fmt::Formatter<'_>,
    from: &Bound<'_, PyAny>,
    to: &str,
) -> std::fmt::Result {
    write!(
        f,
        "'{}' object cannot be converted to '{}'",
        from.get_type().qualname().map_err(|_| std::fmt::Error)?,
        to
    )
}

#[track_caller]
pub fn panic_after_error(_py: Python<'_>) -> ! {
    unsafe {
        ffi::PyErr_Print();
    }
    panic!("Python API call failed");
}

/// Returns Ok if the error code is not -1.
#[inline]
pub(crate) fn error_on_minusone<T: SignedInteger>(py: Python<'_>, result: T) -> PyResult<()> {
    if result != T::MINUS_ONE {
        Ok(())
    } else {
        Err(PyErr::fetch(py))
    }
}

pub(crate) trait SignedInteger: Eq {
    const MINUS_ONE: Self;
}

macro_rules! impl_signed_integer {
    ($t:ty) => {
        impl SignedInteger for $t {
            const MINUS_ONE: Self = -1;
        }
    };
}

impl_signed_integer!(i8);
impl_signed_integer!(i16);
impl_signed_integer!(i32);
impl_signed_integer!(i64);
impl_signed_integer!(i128);
impl_signed_integer!(isize);

#[cfg(test)]
mod tests {
    use super::PyErrState;
    use crate::exceptions::{self, PyTypeError, PyValueError};
    use crate::{ffi, PyErr, PyTypeInfo, Python};

    #[test]
    fn no_error() {
        assert!(Python::with_gil(PyErr::take).is_none());
    }

    #[test]
    fn set_valueerror() {
        Python::with_gil(|py| {
            let err: PyErr = exceptions::PyValueError::new_err("some exception message");
            assert!(err.is_instance_of::<exceptions::PyValueError>(py));
            err.restore(py);
            assert!(PyErr::occurred(py));
            let err = PyErr::fetch(py);
            assert!(err.is_instance_of::<exceptions::PyValueError>(py));
            assert_eq!(err.to_string(), "ValueError: some exception message");
        })
    }

    #[test]
    fn invalid_error_type() {
        Python::with_gil(|py| {
            let err: PyErr = PyErr::new::<crate::types::PyString, _>(());
            assert!(err.is_instance_of::<exceptions::PyTypeError>(py));
            err.restore(py);
            let err = PyErr::fetch(py);

            assert!(err.is_instance_of::<exceptions::PyTypeError>(py));
            assert_eq!(
                err.to_string(),
                "TypeError: exceptions must derive from BaseException"
            );
        })
    }

    #[test]
    fn set_typeerror() {
        Python::with_gil(|py| {
            let err: PyErr = exceptions::PyTypeError::new_err(());
            err.restore(py);
            assert!(PyErr::occurred(py));
            drop(PyErr::fetch(py));
        });
    }

    #[test]
    #[should_panic(expected = "new panic")]
    fn fetching_panic_exception_resumes_unwind() {
        use crate::panic::PanicException;

        Python::with_gil(|py| {
            let err: PyErr = PanicException::new_err("new panic");
            err.restore(py);
            assert!(PyErr::occurred(py));

            // should resume unwind
            let _ = PyErr::fetch(py);
        });
    }

    #[test]
    #[should_panic(expected = "new panic")]
    #[cfg(not(Py_3_12))]
    fn fetching_normalized_panic_exception_resumes_unwind() {
        use crate::panic::PanicException;

        Python::with_gil(|py| {
            let err: PyErr = PanicException::new_err("new panic");
            // Restoring an error doesn't normalize it before Python 3.12,
            // so we have to explicitly test this case.
            let _ = err.normalized(py);
            err.restore(py);
            assert!(PyErr::occurred(py));

            // should resume unwind
            let _ = PyErr::fetch(py);
        });
    }

    #[test]
    fn err_debug() {
        // Debug representation should be like the following (without the newlines):
        // PyErr {
        //     type: <class 'Exception'>,
        //     value: Exception('banana'),
        //     traceback:  Some(\"Traceback (most recent call last):\\n  File \\\"<string>\\\", line 1, in <module>\\n\")
        // }

        Python::with_gil(|py| {
            let err = py
                .run(ffi::c_str!("raise Exception('banana')"), None, None)
                .expect_err("raising should have given us an error");

            let debug_str = format!("{:?}", err);
            assert!(debug_str.starts_with("PyErr { "));
            assert!(debug_str.ends_with(" }"));

            // Strip "PyErr { " and " }". Split into 3 substrings to separate type,
            // value, and traceback while not splitting the string within traceback.
            let mut fields = debug_str["PyErr { ".len()..debug_str.len() - 2].splitn(3, ", ");

            assert_eq!(fields.next().unwrap(), "type: <class 'Exception'>");
            assert_eq!(fields.next().unwrap(), "value: Exception('banana')");
            assert_eq!(
                fields.next().unwrap(),
                "traceback: Some(\"Traceback (most recent call last):\\n  File \\\"<string>\\\", line 1, in <module>\\n\")"
            );

            assert!(fields.next().is_none());
        });
    }

    #[test]
    fn err_display() {
        Python::with_gil(|py| {
            let err = py
                .run(ffi::c_str!("raise Exception('banana')"), None, None)
                .expect_err("raising should have given us an error");
            assert_eq!(err.to_string(), "Exception: banana");
        });
    }

    #[test]
    fn test_pyerr_send_sync() {
        fn is_send<T: Send>() {}
        fn is_sync<T: Sync>() {}

        is_send::<PyErr>();
        is_sync::<PyErr>();

        is_send::<PyErrState>();
        is_sync::<PyErrState>();
    }

    #[test]
    fn test_pyerr_matches() {
        Python::with_gil(|py| {
            let err = PyErr::new::<PyValueError, _>("foo");
            assert!(err.matches(py, PyValueError::type_object(py)).unwrap());

            assert!(err
                .matches(
                    py,
                    (PyValueError::type_object(py), PyTypeError::type_object(py))
                )
                .unwrap());

            assert!(!err.matches(py, PyTypeError::type_object(py)).unwrap());

            // String is not a valid exception class, so we should get a TypeError
            let err: PyErr = PyErr::from_type(crate::types::PyString::type_object(py), "foo");
            assert!(err.matches(py, PyTypeError::type_object(py)).unwrap());
        })
    }

    #[test]
    fn test_pyerr_cause() {
        Python::with_gil(|py| {
            let err = py
                .run(ffi::c_str!("raise Exception('banana')"), None, None)
                .expect_err("raising should have given us an error");
            assert!(err.cause(py).is_none());

            let err = py
                .run(
                    ffi::c_str!("raise Exception('banana') from Exception('apple')"),
                    None,
                    None,
                )
                .expect_err("raising should have given us an error");
            let cause = err
                .cause(py)
                .expect("raising from should have given us a cause");
            assert_eq!(cause.to_string(), "Exception: apple");

            err.set_cause(py, None);
            assert!(err.cause(py).is_none());

            let new_cause = exceptions::PyValueError::new_err("orange");
            err.set_cause(py, Some(new_cause));
            let cause = err
                .cause(py)
                .expect("set_cause should have given us a cause");
            assert_eq!(cause.to_string(), "ValueError: orange");
        });
    }

    #[test]
    fn warnings() {
        use crate::types::any::PyAnyMethods;
        // Note: although the warning filter is interpreter global, keeping the
        // GIL locked should prevent effects to be visible to other testing
        // threads.
        Python::with_gil(|py| {
            let cls = py.get_type::<exceptions::PyUserWarning>();

            // Reset warning filter to default state
            let warnings = py.import("warnings").unwrap();
            warnings.call_method0("resetwarnings").unwrap();

            // First, test the warning is emitted
            #[cfg(not(Py_GIL_DISABLED))]
            assert_warnings!(
                py,
                { PyErr::warn(py, &cls, ffi::c_str!("I am warning you"), 0).unwrap() },
                [(exceptions::PyUserWarning, "I am warning you")]
            );

            // Test with raising
            warnings
                .call_method1("simplefilter", ("error", &cls))
                .unwrap();
            PyErr::warn(py, &cls, ffi::c_str!("I am warning you"), 0).unwrap_err();

            // Test with error for an explicit module
            warnings.call_method0("resetwarnings").unwrap();
            warnings
                .call_method1("filterwarnings", ("error", "", &cls, "pyo3test"))
                .unwrap();

            // This has the wrong module and will not raise, just be emitted
            #[cfg(not(Py_GIL_DISABLED))]
            assert_warnings!(
                py,
                { PyErr::warn(py, &cls, ffi::c_str!("I am warning you"), 0).unwrap() },
                [(exceptions::PyUserWarning, "I am warning you")]
            );

            let err = PyErr::warn_explicit(
                py,
                &cls,
                ffi::c_str!("I am warning you"),
                ffi::c_str!("pyo3test.py"),
                427,
                None,
                None,
            )
            .unwrap_err();
            assert!(err
                .value(py)
                .getattr("args")
                .unwrap()
                .get_item(0)
                .unwrap()
                .eq("I am warning you")
                .unwrap());

            // Finally, reset filter again
            warnings.call_method0("resetwarnings").unwrap();
        });
    }
}
