error: expected `cancel_handle` or `from_py_with`
 --> tests/ui/invalid_argument_attributes.rs:4:29
  |
4 | fn invalid_attribute(#[pyo3(get)] _param: String) {}
  |                             ^^^

error: expected `=`
 --> tests/ui/invalid_argument_attributes.rs:7:45
  |
7 | fn from_py_with_no_value(#[pyo3(from_py_with)] _param: String) {}
  |                                             ^

error: expected `cancel_handle` or `from_py_with`
  --> tests/ui/invalid_argument_attributes.rs:10:31
   |
10 | fn from_py_with_string(#[pyo3("from_py_with")] _param: String) {}
   |                               ^^^^^^^^^^^^^^

error: `from_py_with` may only be specified once per argument
  --> tests/ui/invalid_argument_attributes.rs:16:54
   |
16 | fn from_py_with_repeated(#[pyo3(from_py_with = func, from_py_with = func)] _param: String) {}
   |                                                      ^^^^^^^^^^^^

error: expected identifier
  --> tests/ui/invalid_argument_attributes.rs:23:28
   |
23 | fn f(#[pyo3(from_py_with = "bytes_from_py")] _bytes: Vec<u8>) {}
   |                            ^^^^^^^^^^^^^^^

error[E0425]: cannot find value `func` in this scope
  --> tests/ui/invalid_argument_attributes.rs:13:55
   |
13 | fn from_py_with_value_not_found(#[pyo3(from_py_with = func)] _param: String) {}
   |                                                       ^^^^ not found in this scope
